<?xml version="1.0" encoding="UTF-8"?>
<testng-results>
  <reporter-output>
  </reporter-output>
  <suite name="SuiteB" duration-ms="8" started-at="2016-10-01T23:49:22Z" finished-at="2016-10-01T23:49:22Z">
    <groups>
    </groups>
    <test name="Test B1" duration-ms="3" started-at="2016-10-01T23:49:22Z" finished-at="2016-10-01T23:49:22Z">
      <class name="reportSuiteB.TestB1">
        <test-method status="PASS" signature="testB1_1()" name="testB1_1" duration-ms="1" started-at="2016-10-01T23:49:22Z" finished-at="2016-10-01T23:49:22Z">
        </test-method>
        <test-method status="PASS" signature="testB1_2()" name="testB1_2" duration-ms="1" started-at="2016-10-01T23:49:22Z" finished-at="2016-10-01T23:49:22Z">
        </test-method>
        <test-method status="PASS" signature="testB1_3()" name="testB1_3" duration-ms="1" started-at="2016-10-01T23:49:22Z" finished-at="2016-10-01T23:49:22Z">
        </test-method>
      </class>
    </test>
    <test name="Test B2" duration-ms="2" started-at="2016-10-01T23:49:22Z" finished-at="2016-10-01T23:49:22Z">
      <class name="reportSuiteB.TestB2">
        <test-method status="SKIP" signature="testB2_2()" name="testB2_2" duration-ms="1" started-at="2016-10-01T23:49:22Z" finished-at="2016-10-01T23:49:22Z">
          <exception class="org.testng.SkipException">
            <message>
              <![CDATA[Skipping test due to some failure]]>
            </message>
            <full-stacktrace>
              <![CDATA[org.testng.SkipException: Skipping test due to some failure
	at reportSuiteB.TestB2.testB2_2(TestB2.java:17)
	at sun.reflect.NativeMethodAccessorImpl.invoke0(Native Method)
	at sun.reflect.NativeMethodAccessorImpl.invoke(NativeMethodAccessorImpl.java:57)
	at sun.reflect.DelegatingMethodAccessorImpl.invoke(DelegatingMethodAccessorImpl.java:43)
	at java.lang.reflect.Method.invoke(Method.java:606)
	at org.testng.internal.MethodInvocationHelper.invokeMethod(MethodInvocationHelper.java:74)
	at org.testng.internal.Invoker.invokeMethod(Invoker.java:673)
	at org.testng.internal.Invoker.invokeTestMethod(Invoker.java:846)
	at org.testng.internal.Invoker.invokeTestMethods(Invoker.java:1170)
	at org.testng.internal.TestMethodWorker.invokeTestMethods(TestMethodWorker.java:125)
	at org.testng.internal.TestMethodWorker.run(TestMethodWorker.java:109)
	at org.testng.TestRunner.runWorkers(TestRunner.java:1125)
	at org.testng.TestRunner.privateRun(TestRunner.java:749)
	at org.testng.TestRunner.run(TestRunner.java:600)
	at org.testng.SuiteRunner.runTest(SuiteRunner.java:317)
	at org.testng.SuiteRunner.runSequentially(SuiteRunner.java:312)
	at org.testng.SuiteRunner.privateRun(SuiteRunner.java:274)
	at org.testng.SuiteRunner.run(SuiteRunner.java:223)
	at org.testng.SuiteRunnerWorker.runSuite(SuiteRunnerWorker.java:52)
	at org.testng.SuiteRunnerWorker.run(SuiteRunnerWorker.java:86)
	at org.testng.TestNG.runSuitesSequentially(TestNG.java:1031)
	at org.testng.TestNG.runSuitesSequentially(TestNG.java:1027)
	at org.testng.TestNG.runSuitesLocally(TestNG.java:956)
	at org.testng.TestNG.run(TestNG.java:892)
	at org.testng.TestNG.privateMain(TestNG.java:1174)
	at org.testng.TestNG.main(TestNG.java:1138)
]]>
            </full-stacktrace>
          </exception>
        </test-method>
        <test-method status="PASS" signature="testB2_1()" name="testB2_1" duration-ms="0" started-at="2016-10-01T23:49:22Z" finished-at="2016-10-01T23:49:22Z">
        </test-method>
        <test-method status="FAIL" signature="testB2_3()" name="testB2_3" duration-ms="0" started-at="2016-10-01T23:49:22Z" finished-at="2016-10-01T23:49:22Z">
          <exception class="java.lang.AssertionError">
            <message>
              <![CDATA[Faliure Message]]>
            </message>
            <full-stacktrace>
              <![CDATA[java.lang.AssertionError: Faliure Message
	at org.testng.Assert.fail(Assert.java:89)
	at reportSuiteB.TestB2.testB2_3(TestB2.java:23)
	at sun.reflect.NativeMethodAccessorImpl.invoke0(Native Method)
	at sun.reflect.NativeMethodAccessorImpl.invoke(NativeMethodAccessorImpl.java:57)
	at sun.reflect.DelegatingMethodAccessorImpl.invoke(DelegatingMethodAccessorImpl.java:43)
	at java.lang.reflect.Method.invoke(Method.java:606)
	at org.testng.internal.MethodInvocationHelper.invokeMethod(MethodInvocationHelper.java:74)
	at org.testng.internal.Invoker.invokeMethod(Invoker.java:673)
	at org.testng.internal.Invoker.invokeTestMethod(Invoker.java:846)
	at org.testng.internal.Invoker.invokeTestMethods(Invoker.java:1170)
	at org.testng.internal.TestMethodWorker.invokeTestMethods(TestMethodWorker.java:125)
	at org.testng.internal.TestMethodWorker.run(TestMethodWorker.java:109)
	at org.testng.TestRunner.runWorkers(TestRunner.java:1125)
	at org.testng.TestRunner.privateRun(TestRunner.java:749)
	at org.testng.TestRunner.run(TestRunner.java:600)
	at org.testng.SuiteRunner.runTest(SuiteRunner.java:317)
	at org.testng.SuiteRunner.runSequentially(SuiteRunner.java:312)
	at org.testng.SuiteRunner.privateRun(SuiteRunner.java:274)
	at org.testng.SuiteRunner.run(SuiteRunner.java:223)
	at org.testng.SuiteRunnerWorker.runSuite(SuiteRunnerWorker.java:52)
	at org.testng.SuiteRunnerWorker.run(SuiteRunnerWorker.java:86)
	at org.testng.TestNG.runSuitesSequentially(TestNG.java:1031)
	at org.testng.TestNG.runSuitesSequentially(TestNG.java:1027)
	at org.testng.TestNG.runSuitesLocally(TestNG.java:956)
	at org.testng.TestNG.run(TestNG.java:892)
	at org.testng.TestNG.privateMain(TestNG.java:1174)
	at org.testng.TestNG.main(TestNG.java:1138)
]]>
            </full-stacktrace>
          </exception>
        </test-method>
      </class>
    </test>
  </suite>
  <suite name="SuiteA" duration-ms="66" started-at="2016-10-01T23:49:22Z" finished-at="2016-10-01T23:49:22Z">
    <groups>
    </groups>
    <test name="Test A1" duration-ms="20" started-at="2016-10-01T23:49:22Z" finished-at="2016-10-01T23:49:22Z">
      <class name="reportSuiteA.TestA1">
        <test-method status="PASS" signature="testA1_1()" name="testA1_1" duration-ms="7" started-at="2016-10-01T23:49:22Z" finished-at="2016-10-01T23:49:22Z">
        </test-method>
        <test-method status="FAIL" signature="testA1_2()" name="testA1_2" duration-ms="2" started-at="2016-10-01T23:49:22Z" finished-at="2016-10-01T23:49:22Z">
          <exception class="java.lang.AssertionError">
            <message>
              <![CDATA[Faliure Message]]>
            </message>
            <full-stacktrace>
              <![CDATA[java.lang.AssertionError: Faliure Message
	at org.testng.Assert.fail(Assert.java:89)
	at reportSuiteA.TestA1.testA1_2(TestA1.java:17)
	at sun.reflect.NativeMethodAccessorImpl.invoke0(Native Method)
	at sun.reflect.NativeMethodAccessorImpl.invoke(NativeMethodAccessorImpl.java:57)
	at sun.reflect.DelegatingMethodAccessorImpl.invoke(DelegatingMethodAccessorImpl.java:43)
	at java.lang.reflect.Method.invoke(Method.java:606)
	at org.testng.internal.MethodInvocationHelper.invokeMethod(MethodInvocationHelper.java:74)
	at org.testng.internal.Invoker.invokeMethod(Invoker.java:673)
	at org.testng.internal.Invoker.invokeTestMethod(Invoker.java:846)
	at org.testng.internal.Invoker.invokeTestMethods(Invoker.java:1170)
	at org.testng.internal.TestMethodWorker.invokeTestMethods(TestMethodWorker.java:125)
	at org.testng.internal.TestMethodWorker.run(TestMethodWorker.java:109)
	at org.testng.TestRunner.runWorkers(TestRunner.java:1125)
	at org.testng.TestRunner.privateRun(TestRunner.java:749)
	at org.testng.TestRunner.run(TestRunner.java:600)
	at org.testng.SuiteRunner.runTest(SuiteRunner.java:317)
	at org.testng.SuiteRunner.runSequentially(SuiteRunner.java:312)
	at org.testng.SuiteRunner.privateRun(SuiteRunner.java:274)
	at org.testng.SuiteRunner.run(SuiteRunner.java:223)
	at org.testng.SuiteRunnerWorker.runSuite(SuiteRunnerWorker.java:52)
	at org.testng.SuiteRunnerWorker.run(SuiteRunnerWorker.java:86)
	at org.testng.TestNG.runSuitesSequentially(TestNG.java:1031)
	at org.testng.TestNG.runSuitesSequentially(TestNG.java:1027)
	at org.testng.TestNG.runSuitesLocally(TestNG.java:956)
	at org.testng.TestNG.run(TestNG.java:892)
	at org.testng.TestNG.privateMain(TestNG.java:1174)
	at org.testng.TestNG.main(TestNG.java:1138)
]]>
            </full-stacktrace>
          </exception>
        </test-method>
        <test-method status="SKIP" signature="testA1_3()" name="testA1_3" duration-ms="0" started-at="2016-10-01T23:49:22Z" finished-at="2016-10-01T23:49:22Z">
          <exception class="org.testng.SkipException">
            <message>
              <![CDATA[Skipping test due to some failure]]>
            </message>
            <full-stacktrace>
              <![CDATA[org.testng.SkipException: Skipping test due to some failure
	at reportSuiteA.TestA1.testA1_3(TestA1.java:23)
	at sun.reflect.NativeMethodAccessorImpl.invoke0(Native Method)
	at sun.reflect.NativeMethodAccessorImpl.invoke(NativeMethodAccessorImpl.java:57)
	at sun.reflect.DelegatingMethodAccessorImpl.invoke(DelegatingMethodAccessorImpl.java:43)
	at java.lang.reflect.Method.invoke(Method.java:606)
	at org.testng.internal.MethodInvocationHelper.invokeMethod(MethodInvocationHelper.java:74)
	at org.testng.internal.Invoker.invokeMethod(Invoker.java:673)
	at org.testng.internal.Invoker.invokeTestMethod(Invoker.java:846)
	at org.testng.internal.Invoker.invokeTestMethods(Invoker.java:1170)
	at org.testng.internal.TestMethodWorker.invokeTestMethods(TestMethodWorker.java:125)
	at org.testng.internal.TestMethodWorker.run(TestMethodWorker.java:109)
	at org.testng.TestRunner.runWorkers(TestRunner.java:1125)
	at org.testng.TestRunner.privateRun(TestRunner.java:749)
	at org.testng.TestRunner.run(TestRunner.java:600)
	at org.testng.SuiteRunner.runTest(SuiteRunner.java:317)
	at org.testng.SuiteRunner.runSequentially(SuiteRunner.java:312)
	at org.testng.SuiteRunner.privateRun(SuiteRunner.java:274)
	at org.testng.SuiteRunner.run(SuiteRunner.java:223)
	at org.testng.SuiteRunnerWorker.runSuite(SuiteRunnerWorker.java:52)
	at org.testng.SuiteRunnerWorker.run(SuiteRunnerWorker.java:86)
	at org.testng.TestNG.runSuitesSequentially(TestNG.java:1031)
	at org.testng.TestNG.runSuitesSequentially(TestNG.java:1027)
	at org.testng.TestNG.runSuitesLocally(TestNG.java:956)
	at org.testng.TestNG.run(TestNG.java:892)
	at org.testng.TestNG.privateMain(TestNG.java:1174)
	at org.testng.TestNG.main(TestNG.java:1138)
]]>
            </full-stacktrace>
          </exception>
        </test-method>
      </class>
    </test>
    <test name="Test A2" duration-ms="3" started-at="2016-10-01T23:49:22Z" finished-at="2016-10-01T23:49:22Z">
      <class name="reportSuiteA.TestA2">
        <test-method status="PASS" signature="testA2_1()" name="testA2_1" duration-ms="0" started-at="2016-10-01T23:49:22Z" finished-at="2016-10-01T23:49:22Z">
        </test-method>
        <test-method status="PASS" signature="testA2_2()" name="testA2_2" duration-ms="0" started-at="2016-10-01T23:49:22Z" finished-at="2016-10-01T23:49:22Z">
        </test-method>
        <test-method status="PASS" signature="testA2_3()" name="testA2_3" duration-ms="1" started-at="2016-10-01T23:49:22Z" finished-at="2016-10-01T23:49:22Z">
        </test-method>
      </class>
    </test>
  </suite>
  <suite name="Master Suite" duration-ms="0" started-at="2016-10-01T23:49:22Z" finished-at="2016-10-01T23:49:22Z">
    <groups>
    </groups>
  </suite>
</testng-results>
